Workbook

Sheet Tổng hợp
A1: TỔNG HỢP KẾT QUẢ KIỂM THỬ HỆ THỐNG TIGER SHOP
A2: Học phần: Đánh giá và Kiểm định chất lượng phần mềm
A3: Bộ kịch bản tự động chạy ngày 25/09/2026 trên cơ sở dữ liệu ecommerce_test. Trạng thái ghi theo bốn trạng thái của Bảng 2.25; tỉ lệ đạt tính trên số test case đã thực hiện. Mọi số liệu dưới đây là công thức đếm từ cột Trạng thái của các sheet test case.
A5: 1. KẾT QUẢ THEO NHÓM CHỨC NĂNG (Bảng 3.34)
A6: STT | B6: Mã nhóm | C6: Nhóm chức năng | D6: Số TC | E6: Đã thực hiện | F6: Pass | G6: Fail | H6: Blocked | I6: Chưa thực hiện | J6: Tỉ lệ đạt trên số đã thực hiện
A7: 1 | B7: AUTH | C7: Xác thực và phân quyền | D7: =COUNTA(AUTH!A:A)-1 -> 25 | E7: =F7+G7 -> 20 | F7: =COUNTIF(AUTH!M:M,"Pass") -> 19 | G7: =COUNTIF(AUTH!M:M,"Fail") -> 1 | H7: =COUNTIF(AUTH!M:M,"Blocked") -> 0 | I7: =COUNTIF(AUTH!M:M,"Chưa thực hiện") -> 5 | J7: =IF(E7=0,0,F7/E7) -> 0.95
A8: 2 | B8: PROD | C8: Quản lý sản phẩm và tồn kho | D8: =COUNTA(PROD!A:A)-1 -> 22 | E8: =F8+G8 -> 19 | F8: =COUNTIF(PROD!M:M,"Pass") -> 18 | G8: =COUNTIF(PROD!M:M,"Fail") -> 1 | H8: =COUNTIF(PROD!M:M,"Blocked") -> 0 | I8: =COUNTIF(PROD!M:M,"Chưa thực hiện") -> 3 | J8: =IF(E8=0,0,F8/E8) -> 0.94736842
A9: 3 | B9: ORD | C9: Giỏ hàng và đơn hàng | D9: =COUNTA(ORD!A:A)-1 -> 22 | E9: =F9+G9 -> 15 | F9: =COUNTIF(ORD!M:M,"Pass") -> 14 | G9: =COUNTIF(ORD!M:M,"Fail") -> 1 | H9: =COUNTIF(ORD!M:M,"Blocked") -> 0 | I9: =COUNTIF(ORD!M:M,"Chưa thực hiện") -> 7 | J9: =IF(E9=0,0,F9/E9) -> 0.93333333
A10: 4 | B10: VOUC | C10: Voucher và ví voucher | D10: =COUNTA(VOUC!A:A)-1 -> 12 | E10: =F10+G10 -> 12 | F10: =COUNTIF(VOUC!M:M,"Pass") -> 12 | G10: =COUNTIF(VOUC!M:M,"Fail") -> 0 | H10: =COUNTIF(VOUC!M:M,"Blocked") -> 0 | I10: =COUNTIF(VOUC!M:M,"Chưa thực hiện") -> 0 | J10: =IF(E10=0,0,F10/E10) -> 1
A11: 5 | B11: REV | C11: Đánh giá sản phẩm | D11: =COUNTA(REV!A:A)-1 -> 8 | E11: =F11+G11 -> 8 | F11: =COUNTIF(REV!M:M,"Pass") -> 8 | G11: =COUNTIF(REV!M:M,"Fail") -> 0 | H11: =COUNTIF(REV!M:M,"Blocked") -> 0 | I11: =COUNTIF(REV!M:M,"Chưa thực hiện") -> 0 | J11: =IF(E11=0,0,F11/E11) -> 1
A12: 6 | B12: CHAT | C12: Chat hỗ trợ thời gian thực | D12: =COUNTA(CHAT!A:A)-1 -> 11 | E12: =F12+G12 -> 6 | F12: =COUNTIF(CHAT!M:M,"Pass") -> 5 | G12: =COUNTIF(CHAT!M:M,"Fail") -> 1 | H12: =COUNTIF(CHAT!M:M,"Blocked") -> 0 | I12: =COUNTIF(CHAT!M:M,"Chưa thực hiện") -> 5 | J12: =IF(E12=0,0,F12/E12) -> 0.83333333
A13: 7 | B13: AI | C13: Trợ lý ảo Tiger AI | D13: =COUNTA(AI!A:A)-1 -> 10 | E13: =F13+G13 -> 9 | F13: =COUNTIF(AI!M:M,"Pass") -> 8 | G13: =COUNTIF(AI!M:M,"Fail") -> 1 | H13: =COUNTIF(AI!M:M,"Blocked") -> 0 | I13: =COUNTIF(AI!M:M,"Chưa thực hiện") -> 1 | J13: =IF(E13=0,0,F13/E13) -> 0.88888889
A14: 8 | B14: HR | C14: Ca làm, chấm công và lương | D14: =COUNTA(HR!A:A)-1 -> 15 | E14: =F14+G14 -> 14 | F14: =COUNTIF(HR!M:M,"Pass") -> 14 | G14: =COUNTIF(HR!M:M,"Fail") -> 0 | H14: =COUNTIF(HR!M:M,"Blocked") -> 0 | I14: =COUNTIF(HR!M:M,"Chưa thực hiện") -> 1 | J14: =IF(E14=0,0,F14/E14) -> 1
A15: 9 | B15: ADM | C15: Quản trị hệ thống | D15: =COUNTA(ADM!A:A)-1 -> 10 | E15: =F15+G15 -> 10 | F15: =COUNTIF(ADM!M:M,"Pass") -> 9 | G15: =COUNTIF(ADM!M:M,"Fail") -> 1 | H15: =COUNTIF(ADM!M:M,"Blocked") -> 0 | I15: =COUNTIF(ADM!M:M,"Chưa thực hiện") -> 0 | J15: =IF(E15=0,0,F15/E15) -> 0.9
C16: TỔNG CỘNG | D16: =SUM(D7:D15) -> 135 | E16: =SUM(E7:E15) -> 113 | F16: =SUM(F7:F15) -> 107 | G16: =SUM(G7:G15) -> 6 | H16: =SUM(H7:H15) -> 0 | I16: =SUM(I7:I15) -> 22 | J16: =IF(E16=0,0,F16/E16) -> 0.94690265
C17: Kiểm tra: Số TC bằng tổng bốn trạng thái | D17: =IF(D16=F16+G16+H16+I16,"Khớp","Lệch") -> Khớp
A19: 2. ĐỐI CHIẾU VỚI TIÊU CHÍ KẾT THÚC KIỂM THỬ (Bảng 2.27)
A20: STT | B20: Chỉ số | D20: Giá trị | E20: Ngưỡng | F20: Kết luận
A21: 1 | B21: Tỉ lệ test case đã thực thi | D21: =IF(D16=0,0,E16/D16) -> 0.83703704 | E21: 1 | F21: =IF(ROUND(D21,4)>=E21,"Đạt","Chưa đạt") -> Chưa đạt
A22: 2 | B22: Tỉ lệ đạt trên số test case đã thực thi | D22: =J16 -> 0.94690265 | E22: 0.95 | F22: =IF(ROUND(D22,4)>=E22,"Đạt","Chưa đạt") -> Chưa đạt
A23: 3 | B23: Tỉ lệ Use Case có test case | D23: =COUNTIF('Truy vết UC và TC'!B4:B28,">0")/COUNTA('Truy vết UC và TC'!A4:A28) -> 1 | E23: 1 | F23: =IF(ROUND(D23,4)>=E23,"Đạt","Chưa đạt") -> Đạt
B24: Ngưỡng lấy theo tiêu chí kết thúc ở Bảng 2.27 của Chương II.
A26: 3. KẾT QUẢ THEO LOẠI KIỂM THỬ VÀ MỨC ƯU TIÊN (Bảng 3.3 và Bảng 3.35)
A27: STT | B27: Phân loại | D27: Số TC | E27: Tỉ lệ trên tổng số TC | F27: Pass | G27: Fail | H27: Đã thực hiện | I27: Chưa thực hiện | J27: Tỉ lệ đạt trên số đã thực hiện
A28: 1 | B28: Positive | D28: =COUNTIF('Toàn bộ Test Case'!I:I,"Positive") -> 70 | E28: =IF($D$16=0,0,D28/$D$16) -> 0.51851852 | F28: =COUNTIFS('Toàn bộ Test Case'!I:I,"Positive",'Toàn bộ Test Case'!M:M,"Pass") -> 55 | G28: =COUNTIFS('Toàn bộ Test Case'!I:I,"Positive",'Toàn bộ Test Case'!M:M,"Fail") -> 3 | H28: =F28+G28 -> 58 | I28: =COUNTIFS('Toàn bộ Test Case'!I:I,"Positive",'Toàn bộ Test Case'!M:M,"Chưa thực hiện") -> 12 | J28: =IF(H28=0,0,F28/H28) -> 0.94827586
A29: 2 | B29: Negative | D29: =COUNTIF('Toàn bộ Test Case'!I:I,"Negative") -> 34 | E29: =IF($D$16=0,0,D29/$D$16) -> 0.25185185 | F29: =COUNTIFS('Toàn bộ Test Case'!I:I,"Negative",'Toàn bộ Test Case'!M:M,"Pass") -> 26 | G29: =COUNTIFS('Toàn bộ Test Case'!I:I,"Negative",'Toàn bộ Test Case'!M:M,"Fail") -> 1 | H29: =F29+G29 -> 27 | I29: =COUNTIFS('Toàn bộ Test Case'!I:I,"Negative",'Toàn bộ Test Case'!M:M,"Chưa thực hiện") -> 7 | J29: =IF(H29=0,0,F29/H29) -> 0.96296296
A30: 3 | B30: Boundary | D30: =COUNTIF('Toàn bộ Test Case'!I:I,"Boundary") -> 9 | E30: =IF($D$16=0,0,D30/$D$16) -> 0.066666667 | F30: =COUNTIFS('Toàn bộ Test Case'!I:I,"Boundary",'Toàn bộ Test Case'!M:M,"Pass") -> 7 | G30: =COUNTIFS('Toàn bộ Test Case'!I:I,"Boundary",'Toàn bộ Test Case'!M:M,"Fail") -> 0 | H30: =F30+G30 -> 7 | I30: =COUNTIFS('Toàn bộ Test Case'!I:I,"Boundary",'Toàn bộ Test Case'!M:M,"Chưa thực hiện") -> 2 | J30: =IF(H30=0,0,F30/H30) -> 1
A31: 4 | B31: Security | D31: =COUNTIF('Toàn bộ Test Case'!I:I,"Security") -> 22 | E31: =IF($D$16=0,0,D31/$D$16) -> 0.16296296 | F31: =COUNTIFS('Toàn bộ Test Case'!I:I,"Security",'Toàn bộ Test Case'!M:M,"Pass") -> 19 | G31: =COUNTIFS('Toàn bộ Test Case'!I:I,"Security",'Toàn bộ Test Case'!M:M,"Fail") -> 2 | H31: =F31+G31 -> 21 | I31: =COUNTIFS('Toàn bộ Test Case'!I:I,"Security",'Toàn bộ Test Case'!M:M,"Chưa thực hiện") -> 1 | J31: =IF(H31=0,0,F31/H31) -> 0.9047619
A32: 5 | B32: Ưu tiên Cao | D32: =COUNTIF('Toàn bộ Test Case'!J:J,"Cao") -> 110 | E32: =IF($D$16=0,0,D32/$D$16) -> 0.81481481 | F32: =COUNTIFS('Toàn bộ Test Case'!J:J,"Cao",'Toàn bộ Test Case'!M:M,"Pass") -> 92 | G32: =COUNTIFS('Toàn bộ Test Case'!J:J,"Cao",'Toàn bộ Test Case'!M:M,"Fail") -> 6 | H32: =F32+G32 -> 98 | I32: =COUNTIFS('Toàn bộ Test Case'!J:J,"Cao",'Toàn bộ Test Case'!M:M,"Chưa thực hiện") -> 12 | J32: =IF(H32=0,0,F32/H32) -> 0.93877551
A33: 6 | B33: Ưu tiên Trung bình | D33: =COUNTIF('Toàn bộ Test Case'!J:J,"Trung bình") -> 25 | E33: =IF($D$16=0,0,D33/$D$16) -> 0.18518519 | F33: =COUNTIFS('Toàn bộ Test Case'!J:J,"Trung bình",'Toàn bộ Test Case'!M:M,"Pass") -> 15 | G33: =COUNTIFS('Toàn bộ Test Case'!J:J,"Trung bình",'Toàn bộ Test Case'!M:M,"Fail") -> 0 | H33: =F33+G33 -> 15 | I33: =COUNTIFS('Toàn bộ Test Case'!J:J,"Trung bình",'Toàn bộ Test Case'!M:M,"Chưa thực hiện") -> 10 | J33: =IF(H33=0,0,F33/H33) -> 1
A35: 4. PHƯƠNG PHÁP THỰC HIỆN THEO THIẾT KẾ VÀ THEO THỰC TẾ (Bảng 3.4)
A36: STT | B36: Phương pháp theo thiết kế | D36: Số TC | E36: Tỉ lệ trên tổng số TC | F36: Kịch bản Jest | G36: Phép đo riêng | H36: Chưa thực hiện
A37: 1 | B37: Thực thi bằng mã | D37: =COUNTIF('Toàn bộ Test Case'!K:K,"Tự động") -> 119 | E37: =IF($D$16=0,0,D37/$D$16) -> 0.88148148 | F37: =COUNTIFS('Toàn bộ Test Case'!K:K,"Tự động",'Toàn bộ Test Case'!N:N,"Jest + Supertest") -> 105 | G37: =COUNTIFS('Toàn bộ Test Case'!K:K,"Tự động",'Toàn bộ Test Case'!N:N,"Đo trực tiếp với Gemini thật") -> 0 | H37: =COUNTIFS('Toàn bộ Test Case'!K:K,"Tự động",'Toàn bộ Test Case'!M:M,"Chưa thực hiện") -> 14
A38: 2 | B38: Thủ công | D38: =COUNTIF('Toàn bộ Test Case'!K:K,"Thủ công") -> 16 | E38: =IF($D$16=0,0,D38/$D$16) -> 0.11851852 | F38: =COUNTIFS('Toàn bộ Test Case'!K:K,"Thủ công",'Toàn bộ Test Case'!N:N,"Jest + Supertest") -> 7 | G38: =COUNTIFS('Toàn bộ Test Case'!K:K,"Thủ công",'Toàn bộ Test Case'!N:N,"Đo trực tiếp với Gemini thật") -> 1 | H38: =COUNTIFS('Toàn bộ Test Case'!K:K,"Thủ công",'Toàn bộ Test Case'!M:M,"Chưa thực hiện") -> 8
B39: TỔNG CỘNG | D39: =SUM(D37:D38) -> 135 | E39: =IF($D$16=0,0,D39/$D$16) -> 1 | F39: =SUM(F37:F38) -> 112 | G39: =SUM(G37:G38) -> 1 | H39: =SUM(H37:H38) -> 22
B40: Bảy test case thiết kế thủ công đã được chuyển thành kịch bản Jest: ORD-014, REV-008, AI-001, AI-005, AI-007, HR-013, ADM-008; AI-008 thực hiện bằng phép đo riêng (mục 5.4.5).
A42: 5. TEST CASE KHÔNG ĐẠT VÀ KHIẾM KHUYẾT LIÊN QUAN (Bảng 3.36)
A43: STT | B43: Mã TC | C43: Use Case và bước bị vi phạm | D43: Mã khiếm khuyết | F43: Mức độ | H43: Vị trí trong mã nguồn
A44: 1 | B44: CHAT-009 | C44: UC21, ngoại lệ 5c | D44: DEF-08 (trùng VUL-01) | F44: Nghiêm trọng | H44: routes/chatRoutes.js, tuyến GET /messages/:threadId
A45: 2 | B45: ADM-005 | C45: UC23, ngoại lệ 3b | D45: DEF-06 (trùng VUL-02) | F45: Nghiêm trọng | H45: userController.resetUserPassword
...

Sheet Toàn bộ Test Case
A1: Mã TC | B1: Nhóm chức năng | C1: UC liên quan | D1: Tiêu đề kiểm thử | E1: Điều kiện tiên quyết | F1: Dữ liệu đầu vào | G1: Các bước thực hiện | H1: Kết quả mong đợi | I1: Loại KT | J1: Mức ưu tiên | K1: Phương pháp | L1: Kết quả thực tế | M1: Trạng thái | N1: Người thực hiện | O1: Ngày thực hiện | P1: Ghi chú
A2: AUTH-001 | B2: Xác thực và phân quyền | C2: UC01 | D2: Đăng ký với dữ liệu hợp lệ | E2: Email chưa tồn tại | F2: name = Nguoi dung moi; email = new.user.[thời điểm]@tigershop.test; password = Test@123; phone = 0912345678; birthday = 2000-05-20 | G2: 1. Gửi POST /api/auth/register 2. Truy vấn bảng users theo email 3. Truy vấn user_vouchers của tài khoản mới | H2: Mã 200, thông báo Register successful; users có role_id = 5, status = active; ví có một voucher chào mừng giảm 50% (hậu điều kiện UC01) | I2: Positive | J2: Cao | K2: Tự động | L2: Mã 200, Register successful; role_id = 5, status = active; ví có đúng một voucher value = 50. Voucher được ghi sau khi phản hồi đã trả về nên kịch bản phải chờ tối đa 3 giây mới thấy bản ghi (liên quan DEF-01) | M2: Pass | N2: Jest + Supertest | O2: 25/09/2026 | P2: Quan sát được DEF-01: voucher chào mừng ghi sau phản hồi, không cùng giao dịch
A3: AUTH-002 | B3: Xác thực và phân quyền | C3: UC01 | D3: Đăng ký khi bỏ trống họ tên | E3: Máy chủ đang chạy; không cần đăng nhập | F3: name rỗng; các trường khác hợp lệ | G3: 1. Gửi POST /api/auth/register | H3: Mã 400, thông báo Thiếu thông tin đăng ký (ngoại lệ 5a) | I3: Negative | J3: Cao | K3: Tự động | L3: Mã 400, Thiếu thông tin đăng ký | M3: Pass | N3: Jest + Supertest | O3: 25/09/2026
A4: AUTH-003 | B4: Xác thực và phân quyền | C4: UC01 | D4: Đăng ký khi bỏ trống email | E4: Máy chủ đang chạy; không cần đăng nhập | F4: email rỗng; các trường khác hợp lệ | G4: 1. Gửi POST /api/auth/register | H4: Mã 400, thông báo Thiếu thông tin đăng ký (ngoại lệ 5a) | I4: Negative | J4: Cao | K4: Tự động | L4: Mã 400, Thiếu thông tin đăng ký | M4: Pass | N4: Jest + Supertest | O4: 25/09/2026
A5: AUTH-004 | B5: Xác thực và phân quyền | C5: UC01 | D5: Đăng ký khi bỏ trống mật khẩu | E5: Máy chủ đang chạy; không cần đăng nhập | F5: password rỗng; các trường khác hợp lệ | G5: 1. Gửi POST /api/auth/register | H5: Mã 400, thông báo Thiếu thông tin đăng ký (ngoại lệ 5a) | I5: Negative | J5: Cao | K5: Tự động | L5: Mã 400, Thiếu thông tin đăng ký | M5: Pass | N5: Jest + Supertest | O5: 25/09/2026
A6: AUTH-005 | B6: Xác thực và phân quyền | C6: UC01 | D6: Đăng ký khi bỏ trống số điện thoại | E6: Máy chủ đang chạy; không cần đăng nhập | F6: phone rỗng; các trường khác hợp lệ | G6: 1. Gửi POST /api/auth/register | H6: Mã 400, thông báo Thiếu thông tin đăng ký (ngoại lệ 5a) | I6: Negative | J6: Trung bình | K6: Tự động | L6: Mã 400, Thiếu thông tin đăng ký | M6: Pass | N6: Jest + Supertest | O6: 25/09/2026
A7: AUTH-006 | B7: Xác thực và phân quyền | C7: UC01 | D7: Đăng ký với email đã tồn tại | E7: customer1@tigershop.test có sẵn trong dữ liệu mẫu | F7: email = customer1@tigershop.test; các trường khác hợp lệ | G7: 1. Gửi POST /api/auth/register 2. Đếm bản ghi users có email này | H7: Từ chối đăng ký, mã 409 kèm thông báo thư điện tử đã được sử dụng; không phát sinh bản ghi trùng (ngoại lệ 6a) | I7: Negative | J7: Cao | K7: Tự động | L7: Mã 500, thông báo Email đã tồn tại; số bản ghi vẫn là 1 nhờ ràng buộc UNIQUE | M7: Fail | N7: Jest + Supertest | O7: 25/09/2026 | P7: Khiếm khuyết DEF-12, mức Thấp (Bảng 3.36)
A8: AUTH-007 | B8: Xác thực và phân quyền | C8: UC01 | D8: Mật khẩu xác nhận không khớp | E8: Đang ở trang /register | F8: password = Test@123; confirmPassword = Test@456 | G8: 1. Nhập hai mật khẩu khác nhau 2. Nhấn Đăng ký | H8: Giao diện báo lỗi xác nhận mật khẩu và không gửi yêu cầu tới máy chủ (Hình 1.7) | I8: Negative | J8: Cao | K8: Tự động | L8: Chưa có kết quả; kiểm tra này nằm hoàn toàn trong Register.js | M8: Chưa thực hiện | P8: Lý do: chức năng nằm hoàn toàn ở giao diện, thuộc giai đoạn 6 chưa triển khai (Bảng 3.38, dòng 1)
A9: AUTH-008 | B9: Xác thực và phân quyền | C9: UC01 | D9: Đăng ký với email sai định dạng | E9: Đang ở trang /register | F9: email = abc@@test | G9: 1. Nhập email sai định dạng 2. Nhấn Đăng ký | H9: Giao diện chặn gửi biểu mẫu và cảnh báo định dạng email (Hình 1.7) | I9: Negative | J9: Trung bình | K9: Tự động | L9: Chưa có kết quả; kiểm tra này nằm hoàn toàn trong Register.js | M9: Chưa thực hiện | P9: Lý do: chức năng nằm hoàn toàn ở giao diện, thuộc giai đoạn 6 chưa triển khai (Bảng 3.38, dòng 1)
A10: AUTH-009 | B10: Xác thực và phân quyền | C10: UC01 | D10: Mật khẩu được băm trước khi lưu | E10: Đăng ký thành công một tài khoản mới | F10: email = hash.check.[thời điểm]@tigershop.test; password = Test@123 | G10: 1. Đăng ký tài khoản 2. Đọc cột password theo email 3. So khớp bằng bcrypt.compare | H10: Cột password là chuỗi băm bcrypt, khác mật khẩu gốc (bước 6; mục 1.3.3) | I10: Security | J10: Cao | K10: Tự động | L10: Giá trị lưu khác mật khẩu gốc, khớp mẫu chuỗi băm bcrypt; bcrypt.compare với mật khẩu gốc trả về true | M10: Pass | N10: Jest + Supertest | O10: 25/09/2026
A11: AUTH-010 | B11: Xác thực và phân quyền | C11: UC01 | D11: Voucher chào mừng được phát tự động | E11: Vừa đăng ký tài khoản mới | F11: tài khoản tạo ở AUTH-001 | G11: 1. Đăng nhập tài khoản mới 2. Mở trang Voucher của tôi | H11: Ví có đúng một voucher giảm 50%, áp dụng cho đơn từ 50.000 đ, giảm tối đa 100.000 đ, hiệu lực 30 ngày (bước 7) | I11: Positive | J11: Trung bình | K11: Thủ công | L11: Chưa kiểm tra trên giao diện. Kịch bản AUTH-001 mới xác nhận giá trị giảm 50%; đơn tối thiểu, mức giảm tối đa và hạn dùng chưa được đối chiếu | M11: Chưa thực hiện | P11: Lý do: kịch bản hiện có chưa đủ tin cậy làm bằng chứng (Bảng 3.38, dòng 2)
A12: AUTH-011 | B12: Xác thực và phân quyền | C12: UC01 | D12: Giới hạn tần suất trên nhóm API xác thực | E12: Bộ giới hạn thật, không giả lập | F12: 13 yêu cầu POST /api/auth/login liên tiếp từ cùng một địa chỉ | G12: 1. Gửi liên tiếp 13 yêu cầu 2. Ghi mã trạng thái của từng yêu cầu | H12: Mười yêu cầu đầu được xử lý bình thường; từ yêu cầu thứ 11 trả mã 429 (ngoại lệ 4a) | I12: Security | J12: Cao | K12: Tự động | L12: Yêu cầu 1 đến 10 được xử lý (mã 401 vì email không tồn tại); yêu cầu 11 đến 13 trả mã 429. Kịch bản AUTH-011b xác nhận thông báo tiếng Việt có cụm từ quá nhanh | M12: Pass | N12: Jest + Supertest | O12: 25/09/2026
A13: AUTH-012 | B13: Xác thực và phân quyền | C13: UC02 | D13: Đăng nhập tài khoản Quản trị viên | E13: Tài khoản đang hoạt động | F13: admin@tigershop.test; Test@123 | G13: 1. Gửi POST /api/auth/login | H13: Mã 200, trả về token và role = ADMIN; giao diện chuyển tới /admin/dashboard (bước 8) | I13: Positive | J13: Cao | K13: Tự động | L13: Mã 200, token là chuỗi JWT, role = ADMIN. Phần chuyển trang trên giao diện chưa kiểm chứng | M13: Pass | N13: Jest + Supertest | O13: 25/09/2026 | P13: Mức kiểm chứng hạn chế: phần giao diện hoặc thời gian thực chưa kiểm chứng (Bảng 3.37, dòng 4)
A14: AUTH-013 | B14: Xác thực và phân quyền | C14: UC02 | D14: Đăng nhập tài khoản Quản lý | E14: Tài khoản đang hoạt động | F14: manager@tigershop.test; Test@123 | G14: 1. Gửi POST /api/auth/login | H14: Mã 200, role = MANAGER; giao diện chuyển tới /manager/workspace | I14: Positive | J14: Cao | K14: Tự động | L14: Mã 200, token là chuỗi JWT, role = MANAGER. Phần chuyển trang chưa kiểm chứng | M14: Pass | N14: Jest + Supertest | O14: 25/09/2026 | P14: Mức kiểm chứng hạn chế: phần giao diện hoặc thời gian thực chưa kiểm chứng (Bảng 3.37, dòng 4)
A15: AUTH-014 | B15: Xác thực và phân quyền | C15: UC02 | D15: Đăng nhập tài khoản Nhân viên | E15: status = active | F15: staff@tigershop.test; Test@123 | G15: 1. Gửi POST /api/auth/login | H15: Mã 200, role = STAFF; giao diện chuyển tới /staff/workspace | I15: Positive | J15: Cao | K15: Tự động | L15: Mã 200, token là chuỗi JWT, role = STAFF. Phần chuyển trang chưa kiểm chứng | M15: Pass | N15: Jest + Supertest | O15: 25/09/2026 | P15: Mức kiểm chứng hạn chế: phần giao diện hoặc thời gian thực chưa kiểm chứng (Bảng 3.37, dòng 4)
A16: AUTH-015 | B16: Xác thực và phân quyền | C16: UC02 | D16: Đăng nhập tài khoản Khách hàng | E16: Tài khoản đang hoạt động | F16: customer1@tigershop.test; Test@123 | G16: 1. Gửi POST /api/auth/login | H16: Mã 200, role = CUSTOMER; giao diện chuyển tới /home | I16: Positive | J16: Cao | K16: Tự động | L16: Mã 200, token là chuỗi JWT, role = CUSTOMER. Phần chuyển trang chưa kiểm chứng | M16: Pass | N16: Jest + Supertest | O16: 25/09/2026 | P16: Mức kiểm chứng hạn chế: phần giao diện hoặc thời gian thực chưa kiểm chứng (Bảng 3.37, dòng 4)
A17: AUTH-016 | B17: Xác thực và phân quyền | C17: UC02 | D17: Đăng nhập với mật khẩu sai | E17: Tài khoản tồn tại trong hệ thống | F17: customer1@tigershop.test; SaiMatKhau123 | G17: 1. Gửi POST /api/auth/login | H17: Mã 401, thông báo Wrong password; không cấp token (ngoại lệ 6a) | I17: Negative | J17: Cao | K17: Tự động | L17: Mã 401, Wrong password; phản hồi không có trường token | M17: Pass | N17: Jest + Supertest | O17: 25/09/2026 | P17: Hai thông báo khác nhau cho phép dò email (VUL-10, Chương VI)
A18: AUTH-017 | B18: Xác thực và phân quyền | C18: UC02 | D18: Đăng nhập với email không tồn tại | E18: Email khongtontai@tigershop.test chưa từng đăng ký | F18: khongtontai@tigershop.test; Test@123 | G18: 1. Gửi POST /api/auth/login | H18: Mã 401, thông báo User not found (ngoại lệ 4a) | I18: Negative | J18: Cao | K18: Tự động | L18: Mã 401, User not found | M18: Pass | N18: Jest + Supertest | O18: 25/09/2026 | P18: Hai thông báo khác nhau cho phép dò email (VUL-10, Chương VI)
A19: AUTH-018 | B19: Xác thực và phân quyền | C19: UC02 | D19: Bỏ trống email và mật khẩu | E19: Máy chủ đang chạy; không cần đăng nhập | F19: email rỗng; password rỗng | G19: 1. Gửi POST /api/auth/login | H19: Mã 400, thông báo Thiếu email hoặc mật khẩu (ngoại lệ 2a) | I19: Negative | J19: Trung bình | K19: Tự động | L19: Mã 400, Thiếu email hoặc mật khẩu | M19: Pass | N19: Jest + Supertest | O19: 25/09/2026
A20: AUTH-019 | B20: Xác thực và phân quyền | C20: UC02 | D20: Token cấp trước khi tài khoản bị khóa | E20: customer2 đang hoạt động | F20: token của customer2 | G20: 1. Đăng nhập customer2 và gọi GET /api/users/me 2. Đặt is_active = 0 3. Gọi lại GET /api/users/me bằng token cũ | H20: Lần gọi sau khi khóa trả mã 403, thông báo Tài khoản của bạn đã bị khóa. (UC23 ngoại lệ 3a) | I20: Security | J20: Cao | K20: Tự động | L20: Trước khi khóa mã 200; sau khi khóa mã 403 với đúng thông báo. Kịch bản AUTH-019b xác nhận thêm tài khoản customer.locked bị chặn ngay ở bước đăng nhập (mã 403, không cấp token, ngoại lệ 5c) | M20: Pass | N20: Jest + Supertest | O20: 25/09/2026
A21: AUTH-020 | B21: Xác thực và phân quyền | C21: UC03 | D21: Gọi API được bảo vệ khi không gửi token | E21: Máy chủ đang chạy | F21: Yêu cầu GET /api/users/me không có header Authorization | G21: 1. Gửi yêu cầu | H21: Mã 401, thông báo Token không tồn tại | I21: Security | J21: Cao | K21: Tự động | L21: Mã 401, Token không tồn tại | M21: Pass | N21: Jest + Supertest | O21: 25/09/2026
A22: AUTH-021 | B22: Xác thực và phân quyền | C22: UC03 | D22: Gọi API với token sai định dạng hoặc đã hết hạn | E22: Máy chủ đang chạy | F22: Bearer abc.def.ghi; token hợp lệ về chữ ký nhưng hết hạn từ 1 giờ trước | G22: 1. Gửi yêu cầu kèm token sai định dạng 2. Gửi yêu cầu kèm token hết hạn | H22: Cả hai trường hợp trả mã 401, thông báo Token không hợp lệ (ngoại lệ 1a) | I22: Security | J22: Cao | K22: Tự động | L22: Cả hai trả mã 401, Token không hợp lệ (trường hợp hết hạn chạy ở kịch bản AUTH-021b) | M22: Pass | N22: Jest + Supertest | O22: 25/09/2026
A23: AUTH-022 | B23: Xác thực và phân quyền | C23: UC03 | D23: Đăng xuất và xác nhận phiên đã kết thúc | E23: Đang đăng nhập trên trình duyệt | F23: Không | G23: 1. Nhấn Đăng xuất 2. Kiểm tra localStorage 3. Truy cập lại trang cần đăng nhập | H23: Dữ liệu xác thực trong localStorage bị xóa, trình duyệt chuyển về /login và không vào lại được trang bảo vệ (hậu điều kiện UC03) | I23: Positive | J23: Cao | K23: Tự động | L23: Chưa có kết quả; UC03 không có điểm cuối API, toàn bộ xử lý nằm ở giao diện | M23: Chưa thực hiện | P23: Lý do: chức năng nằm hoàn toàn ở giao diện, thuộc giai đoạn 6 chưa triển khai (Bảng 3.38, dòng 1)
A24: AUTH-023 | B24: Xác thực và phân quyền | C24: UC04 | D24: Xem và cập nhật hồ sơ cá nhân | E24: customer1 đã đăng nhập | F24: name = Khach hang mot da doi ten; phone = 0987654321 | G24: 1. Gửi GET /api/users/me 2. Gửi PUT /api/users/me 3. Truy vấn bảng users | H24: Mã 200 ở cả hai yêu cầu; họ tên và số điện thoại mới được lưu (bước 5) | I24: Positive | J24: Cao | K24: Tự động | L24: Cả hai yêu cầu trả mã 200; cột name và phone mang đúng giá trị mới. Phần hiển thị sau khi tải lại trang chưa kiểm chứng | M24: Pass | N24: Jest + Supertest | O24: 25/09/2026 | P24: Mức kiểm chứng hạn chế: phần giao diện hoặc thời gian thực chưa kiểm chứng (Bảng 3.37, dòng 4)
A25: AUTH-024 | B25: Xác thực và phân quyền | C25: UC04 | D25: Đổi mật khẩu với mật khẩu hiện tại không đúng | E25: customer2 đã đăng nhập | F25: currentPassword = SaiMatKhauCu; newPassword = MatKhauMoi@123 | G25: 1. Gửi PUT /api/users/me/change-password 2. So sánh cột password trước và sau | H25: Mã 401, thông báo Mật khẩu hiện tại không đúng; cột password không thay đổi (ngoại lệ 3a) | I25: Security | J25: Cao | K25: Tự động | L25: Yêu cầu bị từ chối (kịch bản kiểm tra mã từ 400 trở lên); cột password giữ nguyên. Kịch bản AUTH-024b xác nhận mật khẩu mới dưới 6 ký tự bị từ chối với mã 400 | M25: Pass | N25: Jest + Supertest | O25: 25/09/2026 | P25: Mức kiểm chứng hạn chế: chỉ kiểm tra mã trạng thái (Bảng 3.37, dòng 1)
A26: AUTH-025 | B26: Xác thực và phân quyền | C26: UC04 | D26: Cập nhật ảnh đại diện | E26: Người dùng đã đăng nhập | F26: avatar.png dung lượng 500 KB | G26: 1. Mở trang Hồ sơ 2. Chọn ảnh mới 3. Nhấn Tải lên | H26: Ảnh được lưu vào thư mục uploads, cột avatar được cập nhật, ảnh mới hiển thị trên thanh điều hướng | I26: Positive | J26: Trung bình | K26: Tự động | L26: Chưa có kết quả đủ tin cậy; kịch bản USR-007 có gọi POST /api/users/me/avatar nhưng tự bỏ qua bước kiểm tra khi máy chủ trả lỗi | M26: Chưa thực hiện | P26: Lý do: kịch bản hiện có chưa đủ tin cậy làm bằng chứng (Bảng 3.38, dòng 2)
A27: PROD-001 | B27: Quản lý sản phẩm và tồn kho | C27: UC05 | D27: Xem danh sách sản phẩm khi chưa đăng nhập | E27: Dữ liệu mẫu có 18 sản phẩm active và 3 sản phẩm pending | F27: Không gửi token | G27: 1. Gửi GET /api/products 2. Đối chiếu với các sản phẩm có status khác active hoặc đã xóa mềm | H27: Mã 200; chỉ có sản phẩm status = active và chưa bị xóa mềm (bước 2) | I27: Positive | J27: Cao | K27: Tự động | L27: Mã 200; không mã sản phẩm pending hay đã xóa mềm nào xuất hiện trong danh sách | M27: Pass | N27: Jest + Supertest | O27: 25/09/2026
A28: PROD-002 | B28: Quản lý sản phẩm và tồn kho | C28: UC05 | D28: Lọc sản phẩm theo danh mục | E28: 4 danh mục đều có sản phẩm | F28: Danh mục đầu tiên có product_count lớn hơn 0 | G28: 1. Gửi GET /api/categories 2. Gửi GET /api/products và lọc theo tên danh mục 3. Đếm trực tiếp trong cơ sở dữ liệu | H28: Chỉ còn sản phẩm thuộc danh mục đã chọn; số lượng khớp số sản phẩm của danh mục (bước 3) | I28: Positive | J28: Cao | K28: Tự động | L28: Số sản phẩm sau khi lọc bằng số đếm trong cơ sở dữ liệu. Thao tác lọc do Shop.js thực hiện trên trình duyệt nên phần hiển thị chưa kiểm chứng | M28: Pass | N28: Jest + Supertest | O28: 25/09/2026 | P28: Mức kiểm chứng hạn chế: phần giao diện hoặc thời gian thực chưa kiểm chứng (Bảng 3.37, dòng 4)
A29: PROD-003 | B29: Quản lý sản phẩm và tồn kho | C29: UC05 | D29: Tìm kiếm theo từ khóa có kết quả | E29: Có sản phẩm tên chứa từ khóa | F29: keyword = Kiem Thu | G29: 1. Nhập từ khóa vào ô tìm kiếm 2. Nhấn tìm kiếm | H29: Hiển thị đúng các sản phẩm có tên chứa từ khóa, không phân biệt chữ hoa và chữ thường (bước 3) | I29: Positive | J29: Trung bình | K29: Tự động | L29: Chưa có kết quả; tìm kiếm là bộ lọc trên trình duyệt trong Shop.js, máy chủ không nhận tham số tìm kiếm | M29: Chưa thực hiện | P29: Lý do: chức năng nằm hoàn toàn ở giao diện, thuộc giai đoạn 6 chưa triển khai (Bảng 3.38, dòng 1)
A30: PROD-004 | B30: Quản lý sản phẩm và tồn kho | C30: UC05 | D30: Tìm kiếm với từ khóa không khớp sản phẩm nào | E30: Đang ở trang danh sách sản phẩm | F30: keyword = zzzzzzzz | G30: 1. Nhập từ khóa 2. Nhấn tìm kiếm | H30: Hiển thị thông báo không tìm thấy, không báo lỗi hệ thống (ngoại lệ 3a) | I30: Negative | J30: Trung bình | K30: Tự động | L30: Chưa có kết quả; cùng lý do với PROD-003 | M30: Chưa thực hiện | P30: Lý do: chức năng nằm hoàn toàn ở giao diện, thuộc giai đoạn 6 chưa triển khai (Bảng 3.38, dòng 1)
A31: PROD-005 | B31: Quản lý sản phẩm và tồn kho | C31: UC05 | D31: Xem chi tiết sản phẩm hợp lệ | E31: Tồn tại sản phẩm có id xác định | F31: Mã của sản phẩm đầu tiên trong danh sách công khai | G31: 1. Gửi GET /api/products/:id | H31: Mã 200; đủ tên, giá, giá gốc, mô tả, ảnh, tồn kho, danh sách biến thể và đánh giá (bước 5) | I31: Positive | J31: Cao | K31: Tự động | L31: Mã 200; có các trường id, name, price, stock. Các trường còn lại chưa được kịch bản kiểm tra | M31: Pass | N31: Jest + Supertest | O31: 25/09/2026 | P31: Mức kiểm chứng hạn chế: chỉ kiểm tra một phần kết quả mong đợi (Bảng 3.37, dòng 2)
A32: PROD-006 | B32: Quản lý sản phẩm và tồn kho | C32: UC05 | D32: Xem chi tiết sản phẩm với mã không tồn tại | E32: Máy chủ đang chạy | F32: productId = 999999 | G32: 1. Gửi GET /api/products/999999 | H32: Mã 404, không trả lỗi 500 (ngoại lệ 4a) | I32: Negative | J32: Trung bình | K32: Tự động | L32: Mã 404 | M32: Pass | N32: Jest + Supertest | O32: 25/09/2026
A33: PROD-007 | B33: Quản lý sản phẩm và tồn kho | C33: UC05 | D33: Xem danh sách biến thể | E33: 3 sản phẩm đầu có biến thể Size S, M, L | F33: Mã của một sản phẩm có biến thể | G33: 1. Gửi GET /api/variants/product/:id | H33: Mã 200; mỗi biến thể có tên, giá và tồn kho riêng | I33: Positive | J33: Cao | K33: Tự động | L33: Mã 200; danh sách có biến thể, bản ghi đầu có đủ variant_name, price, stock | M33: Pass | N33: Jest + Supertest | O33: 25/09/2026
A34: PROD-008 | B34: Quản lý sản phẩm và tồn kho | C34: UC12 | D34: Quản lý thêm sản phẩm mới hợp lệ | E34: Đăng nhập manager@tigershop.test | F34: name = SP cua Manager [thời điểm]; price = 250000; stock = 50; ảnh PNG hợp lệ | G34: 1. Gửi POST /api/products dạng multipart 2. Truy vấn status và manager_id của sản phẩm mới | H34: Mã 200; sản phẩm có status = pending và manager_id là người tạo; chưa hiển thị trên gian hàng cho tới khi được duyệt (bước 5, hậu điều kiện UC12) | I34: Positive | J34: Cao | K34: Tự động | L34: Mã 200; sản phẩm có status = active ngay khi tạo, tức là lên gian hàng mà không qua bước duyệt | M34: Fail | N34: Jest + Supertest | O34: 25/09/2026 | P34: Khiếm khuyết DEF-02, mức Cao (Bảng 3.36); kịch bản PROD-008b ghi nhận thêm DEF-03
A35: PROD-009 | B35: Quản lý sản phẩm và tồn kho | C35: UC12 | D35: Thêm sản phẩm khi bỏ trống tên và giá | E35: Đăng nhập Quản lý | F35: name rỗng; price rỗng | G35: 1. Gửi POST /api/products | H35: Mã 400, thông báo Thiếu thông tin sản phẩm (ngoại lệ 2a) | I35: Negative | J35: Cao | K35: Tự động | L35: Mã 400, Thiếu thông tin sản phẩm | M35: Pass | N35: Jest + Supertest | O35: 25/09/2026
A36: PROD-010 | B36: Quản lý sản phẩm và tồn kho | C36: UC12 | D36: Tải lên tệp sai định dạng | E36: Đăng nhập Quản lý | F36: tailieu.pdf | G36: 1. Gửi POST /api/products kèm tệp pdf ở trường image | H36: Từ chối tải lên, chỉ chấp nhận jpg, jpeg, png, webp (ngoại lệ 3a) | I36: Security | J36: Cao | K36: Tự động | L36: Yêu cầu bị từ chối (kịch bản chỉ kiểm tra mã từ 400 trở lên); bộ lọc fileFilter trong productRoutes.js chặn tệp trước khi ghi đĩa | M36: Pass | N36: Jest + Supertest | O36: 25/09/2026 | P36: Mức kiểm chứng hạn chế: chỉ kiểm tra mã trạng thái (Bảng 3.37, dòng 1)
A37: PROD-011 | B37: Quản lý sản phẩm và tồn kho | C37: UC12 | D37: Tải lên ảnh vượt giới hạn dung lượng | E37: Đăng nhập Quản lý | F37: anh_lon.jpg dung lượng 6 MB | G37: 1. Gửi POST /api/products kèm tệp | H37: Từ chối tải lên vì vượt giới hạn 5 MB (ngoại lệ 3a) | I37: Boundary | J37: Cao | K37: Tự động | L37: Yêu cầu bị từ chối (kịch bản chỉ kiểm tra mã từ 400 trở lên) | M37: Pass | N37: Jest + Supertest | O37: 25/09/2026 | P37: Mức kiểm chứng hạn chế: chỉ kiểm tra mã trạng thái (Bảng 3.37, dòng 1)
A38: PROD-012 | B38: Quản lý sản phẩm và tồn kho | C38: UC12 | D38: Cập nhật thông tin sản phẩm | E38: Đăng nhập Quản lý | F38: price = 299000; stock = 80 | G38: 1. Gửi PUT /api/products/:id 2. Truy vấn price và stock | H38: Mã 200; giá và tồn kho được cập nhật đúng (bước 7) | I38: Positive | J38: Cao | K38: Tự động | L38: Mã 200; price = 299000, stock = 80 | M38: Pass | N38: Jest + Supertest | O38: 25/09/2026
A39: PROD-013 | B39: Quản lý sản phẩm và tồn kho | C39: UC12 | D39: Xóa mềm và khôi phục sản phẩm | E39: Sản phẩm đang active | F39: Mã của một sản phẩm active | G39: 1. Gửi DELETE /api/products/:id 2. Gửi GET /api/products 3. Gửi PATCH /api/products/:id/restore | H39: Sau khi xóa: deleted_at có giá trị, sản phẩm biến mất khỏi gian hàng. Sau khi khôi phục: deleted_at trở về NULL (ngoại lệ 7b) | I39: Positive | J39: Cao | K39: Tự động | L39: Cả hai thao tác trả mã 200; deleted_at có giá trị rồi trở về NULL; trong khoảng giữa, sản phẩm không có trong danh sách công khai | M39: Pass | N39: Jest + Supertest | O39: 25/09/2026
A40: PROD-014 | B40: Quản lý sản phẩm và tồn kho | C40: UC12 | D40: Thêm biến thể cho sản phẩm | E40: Đăng nhập Quản lý | F40: variant_name = Size XL mau do; price = 270000; stock = 20 | G40: 1. Gửi POST /api/variants 2. Truy vấn product_variants | H40: Mã 200, thông báo Thêm variant thành công; bản ghi biến thể được tạo (bước 6) | I40: Positive | J40: Cao | K40: Tự động | L40: Mã 200, Thêm variant thành công; bản ghi có stock = 20 | M40: Pass | N40: Jest + Supertest | O40: 25/09/2026
...

Sheet AUTH
A1: Mã TC | B1: Nhóm chức năng | C1: UC liên quan | D1: Tiêu đề kiểm thử | E1: Điều kiện tiên quyết | F1: Dữ liệu đầu vào | G1: Các bước thực hiện | H1: Kết quả mong đợi | I1: Loại KT | J1: Mức ưu tiên | K1: Phương pháp | L1: Kết quả thực tế | M1: Trạng thái | N1: Người thực hiện | O1: Ngày thực hiện | P1: Ghi chú
A2: AUTH-001 | B2: Xác thực và phân quyền | C2: UC01 | D2: Đăng ký với dữ liệu hợp lệ | E2: Email chưa tồn tại | F2: name = Nguoi dung moi; email = new.user.[thời điểm]@tigershop.test; password = Test@123; phone = 0912345678; birthday = 2000-05-20 | G2: 1. Gửi POST /api/auth/register 2. Truy vấn bảng users theo email 3. Truy vấn user_vouchers của tài khoản mới | H2: Mã 200, thông báo Register successful; users có role_id = 5, status = active; ví có một voucher chào mừng giảm 50% (hậu điều kiện UC01) | I2: Positive | J2: Cao | K2: Tự động | L2: Mã 200, Register successful; role_id = 5, status = active; ví có đúng một voucher value = 50. Voucher được ghi sau khi phản hồi đã trả về nên kịch bản phải chờ tối đa 3 giây mới thấy bản ghi (liên quan DEF-01) | M2: Pass | N2: Jest + Supertest | O2: 25/09/2026 | P2: Quan sát được DEF-01: voucher chào mừng ghi sau phản hồi, không cùng giao dịch
A3: AUTH-002 | B3: Xác thực và phân quyền | C3: UC01 | D3: Đăng ký khi bỏ trống họ tên | E3: Máy chủ đang chạy; không cần đăng nhập | F3: name rỗng; các trường khác hợp lệ | G3: 1. Gửi POST /api/auth/register | H3: Mã 400, thông báo Thiếu thông tin đăng ký (ngoại lệ 5a) | I3: Negative | J3: Cao | K3: Tự động | L3: Mã 400, Thiếu thông tin đăng ký | M3: Pass | N3: Jest + Supertest | O3: 25/09/2026
A4: AUTH-003 | B4: Xác thực và phân quyền | C4: UC01 | D4: Đăng ký khi bỏ trống email | E4: Máy chủ đang chạy; không cần đăng nhập | F4: email rỗng; các trường khác hợp lệ | G4: 1. Gửi POST /api/auth/register | H4: Mã 400, thông báo Thiếu thông tin đăng ký (ngoại lệ 5a) | I4: Negative | J4: Cao | K4: Tự động | L4: Mã 400, Thiếu thông tin đăng ký | M4: Pass | N4: Jest + Supertest | O4: 25/09/2026
A5: AUTH-004 | B5: Xác thực và phân quyền | C5: UC01 | D5: Đăng ký khi bỏ trống mật khẩu | E5: Máy chủ đang chạy; không cần đăng nhập | F5: password rỗng; các trường khác hợp lệ | G5: 1. Gửi POST /api/auth/register | H5: Mã 400, thông báo Thiếu thông tin đăng ký (ngoại lệ 5a) | I5: Negative | J5: Cao | K5: Tự động | L5: Mã 400, Thiếu thông tin đăng ký | M5: Pass | N5: Jest + Supertest | O5: 25/09/2026
A6: AUTH-005 | B6: Xác thực và phân quyền | C6: UC01 | D6: Đăng ký khi bỏ trống số điện thoại | E6: Máy chủ đang chạy; không cần đăng nhập | F6: phone rỗng; các trường khác hợp lệ | G6: 1. Gửi POST /api/auth/register | H6: Mã 400, thông báo Thiếu thông tin đăng ký (ngoại lệ 5a) | I6: Negative | J6: Trung bình | K6: Tự động | L6: Mã 400, Thiếu thông tin đăng ký | M6: Pass | N6: Jest + Supertest | O6: 25/09/2026
A7: AUTH-006 | B7: Xác thực và phân quyền | C7: UC01 | D7: Đăng ký với email đã tồn tại | E7: customer1@tigershop.test có sẵn trong dữ liệu mẫu | F7: email = customer1@tigershop.test; các trường khác hợp lệ | G7: 1. Gửi POST /api/auth/register 2. Đếm bản ghi users có email này | H7: Từ chối đăng ký, mã 409 kèm thông báo thư điện tử đã được sử dụng; không phát sinh bản ghi trùng (ngoại lệ 6a) | I7: Negative | J7: Cao | K7: Tự động | L7: Mã 500, thông báo Email đã tồn tại; số bản ghi vẫn là 1 nhờ ràng buộc UNIQUE | M7: Fail | N7: Jest + Supertest | O7: 25/09/2026 | P7: Khiếm khuyết DEF-12, mức Thấp (Bảng 3.36)
A8: AUTH-007 | B8: Xác thực và phân quyền | C8: UC01 | D8: Mật khẩu xác nhận không khớp | E8: Đang ở trang /register | F8: password = Test@123; confirmPassword = Test@456 | G8: 1. Nhập hai mật khẩu khác nhau 2. Nhấn Đăng ký | H8: Giao diện báo lỗi xác nhận mật khẩu và không gửi yêu cầu tới máy chủ (Hình 1.7) | I8: Negative | J8: Cao | K8: Tự động | L8: Chưa có kết quả; kiểm tra này nằm hoàn toàn trong Register.js | M8: Chưa thực hiện | P8: Lý do: chức năng nằm hoàn toàn ở giao diện, thuộc giai đoạn 6 chưa triển khai (Bảng 3.38, dòng 1)
A9: AUTH-008 | B9: Xác thực và phân quyền | C9: UC01 | D9: Đăng ký với email sai định dạng | E9: Đang ở trang /register | F9: email = abc@@test | G9: 1. Nhập email sai định dạng 2. Nhấn Đăng ký | H9: Giao diện chặn gửi biểu mẫu và cảnh báo định dạng email (Hình 1.7) | I9: Negative | J9: Trung bình | K9: Tự động | L9: Chưa có kết quả; kiểm tra này nằm hoàn toàn trong Register.js | M9: Chưa thực hiện | P9: Lý do: chức năng nằm hoàn toàn ở giao diện, thuộc giai đoạn 6 chưa triển khai (Bảng 3.38, dòng 1)
A10: AUTH-009 | B10: Xác thực và phân quyền | C10: UC01 | D10: Mật khẩu được băm trước khi lưu | E10: Đăng ký thành công một tài khoản mới | F10: email = hash.check.[thời điểm]@tigershop.test; password = Test@123 | G10: 1. Đăng ký tài khoản 2. Đọc cột password theo email 3. So khớp bằng bcrypt.compare | H10: Cột password là chuỗi băm bcrypt, khác mật khẩu gốc (bước 6; mục 1.3.3) | I10: Security | J10: Cao | K10: Tự động | L10: Giá trị lưu khác mật khẩu gốc, khớp mẫu chuỗi băm bcrypt; bcrypt.compare với mật khẩu gốc trả về true | M10: Pass | N10: Jest + Supertest | O10: 25/09/2026
A11: AUTH-010 | B11: Xác thực và phân quyền | C11: UC01 | D11: Voucher chào mừng được phát tự động | E11: Vừa đăng ký tài khoản mới | F11: tài khoản tạo ở AUTH-001 | G11: 1. Đăng nhập tài khoản mới 2. Mở trang Voucher của tôi | H11: Ví có đúng một voucher giảm 50%, áp dụng cho đơn từ 50.000 đ, giảm tối đa 100.000 đ, hiệu lực 30 ngày (bước 7) | I11: Positive | J11: Trung bình | K11: Thủ công | L11: Chưa kiểm tra trên giao diện. Kịch bản AUTH-001 mới xác nhận giá trị giảm 50%; đơn tối thiểu, mức giảm tối đa và hạn dùng chưa được đối chiếu | M11: Chưa thực hiện | P11: Lý do: kịch bản hiện có chưa đủ tin cậy làm bằng chứng (Bảng 3.38, dòng 2)
A12: AUTH-011 | B12: Xác thực và phân quyền | C12: UC01 | D12: Giới hạn tần suất trên nhóm API xác thực | E12: Bộ giới hạn thật, không giả lập | F12: 13 yêu cầu POST /api/auth/login liên tiếp từ cùng một địa chỉ | G12: 1. Gửi liên tiếp 13 yêu cầu 2. Ghi mã trạng thái của từng yêu cầu | H12: Mười yêu cầu đầu được xử lý bình thường; từ yêu cầu thứ 11 trả mã 429 (ngoại lệ 4a) | I12: Security | J12: Cao | K12: Tự động | L12: Yêu cầu 1 đến 10 được xử lý (mã 401 vì email không tồn tại); yêu cầu 11 đến 13 trả mã 429. Kịch bản AUTH-011b xác nhận thông báo tiếng Việt có cụm từ quá nhanh | M12: Pass | N12: Jest + Supertest | O12: 25/09/2026
A13: AUTH-012 | B13: Xác thực và phân quyền | C13: UC02 | D13: Đăng nhập tài khoản Quản trị viên | E13: Tài khoản đang hoạt động | F13: admin@tigershop.test; Test@123 | G13: 1. Gửi POST /api/auth/login | H13: Mã 200, trả về token và role = ADMIN; giao diện chuyển tới /admin/dashboard (bước 8) | I13: Positive | J13: Cao | K13: Tự động | L13: Mã 200, token là chuỗi JWT, role = ADMIN. Phần chuyển trang trên giao diện chưa kiểm chứng | M13: Pass | N13: Jest + Supertest | O13: 25/09/2026 | P13: Mức kiểm chứng hạn chế: phần giao diện hoặc thời gian thực chưa kiểm chứng (Bảng 3.37, dòng 4)
A14: AUTH-013 | B14: Xác thực và phân quyền | C14: UC02 | D14: Đăng nhập tài khoản Quản lý | E14: Tài khoản đang hoạt động | F14: manager@tigershop.test; Test@123 | G14: 1. Gửi POST /api/auth/login | H14: Mã 200, role = MANAGER; giao diện chuyển tới /manager/workspace | I14: Positive | J14: Cao | K14: Tự động | L14: Mã 200, token là chuỗi JWT, role = MANAGER. Phần chuyển trang chưa kiểm chứng | M14: Pass | N14: Jest + Supertest | O14: 25/09/2026 | P14: Mức kiểm chứng hạn chế: phần giao diện hoặc thời gian thực chưa kiểm chứng (Bảng 3.37, dòng 4)
A15: AUTH-014 | B15: Xác thực và phân quyền | C15: UC02 | D15: Đăng nhập tài khoản Nhân viên | E15: status = active | F15: staff@tigershop.test; Test@123 | G15: 1. Gửi POST /api/auth/login | H15: Mã 200, role = STAFF; giao diện chuyển tới /staff/workspace | I15: Positive | J15: Cao | K15: Tự động | L15: Mã 200, token là chuỗi JWT, role = STAFF. Phần chuyển trang chưa kiểm chứng | M15: Pass | N15: Jest + Supertest | O15: 25/09/2026 | P15: Mức kiểm chứng hạn chế: phần giao diện hoặc thời gian thực chưa kiểm chứng (Bảng 3.37, dòng 4)
A16: AUTH-015 | B16: Xác thực và phân quyền | C16: UC02 | D16: Đăng nhập tài khoản Khách hàng | E16: Tài khoản đang hoạt động | F16: customer1@tigershop.test; Test@123 | G16: 1. Gửi POST /api/auth/login | H16: Mã 200, role = CUSTOMER; giao diện chuyển tới /home | I16: Positive | J16: Cao | K16: Tự động | L16: Mã 200, token là chuỗi JWT, role = CUSTOMER. Phần chuyển trang chưa kiểm chứng | M16: Pass | N16: Jest + Supertest | O16: 25/09/2026 | P16: Mức kiểm chứng hạn chế: phần giao diện hoặc thời gian thực chưa kiểm chứng (Bảng 3.37, dòng 4)
A17: AUTH-016 | B17: Xác thực và phân quyền | C17: UC02 | D17: Đăng nhập với mật khẩu sai | E17: Tài khoản tồn tại trong hệ thống | F17: customer1@tigershop.test; SaiMatKhau123 | G17: 1. Gửi POST /api/auth/login | H17: Mã 401, thông báo Wrong password; không cấp token (ngoại lệ 6a) | I17: Negative | J17: Cao | K17: Tự động | L17: Mã 401, Wrong password; phản hồi không có trường token | M17: Pass | N17: Jest + Supertest | O17: 25/09/2026 | P17: Hai thông báo khác nhau cho phép dò email (VUL-10, Chương VI)
A18: AUTH-017 | B18: Xác thực và phân quyền | C18: UC02 | D18: Đăng nhập với email không tồn tại | E18: Email khongtontai@tigershop.test chưa từng đăng ký | F18: khongtontai@tigershop.test; Test@123 | G18: 1. Gửi POST /api/auth/login | H18: Mã 401, thông báo User not found (ngoại lệ 4a) | I18: Negative | J18: Cao | K18: Tự động | L18: Mã 401, User not found | M18: Pass | N18: Jest + Supertest | O18: 25/09/2026 | P18: Hai thông báo khác nhau cho phép dò email (VUL-10, Chương VI)
A19: AUTH-018 | B19: Xác thực và phân quyền | C19: UC02 | D19: Bỏ trống email và mật khẩu | E19: Máy chủ đang chạy; không cần đăng nhập | F19: email rỗng; password rỗng | G19: 1. Gửi POST /api/auth/login | H19: Mã 400, thông báo Thiếu email hoặc mật khẩu (ngoại lệ 2a) | I19: Negative | J19: Trung bình | K19: Tự động | L19: Mã 400, Thiếu email hoặc mật khẩu | M19: Pass | N19: Jest + Supertest | O19: 25/09/2026
A20: AUTH-019 | B20: Xác thực và phân quyền | C20: UC02 | D20: Token cấp trước khi tài khoản bị khóa | E20: customer2 đang hoạt động | F20: token của customer2 | G20: 1. Đăng nhập customer2 và gọi GET /api/users/me 2. Đặt is_active = 0 3. Gọi lại GET /api/users/me bằng token cũ | H20: Lần gọi sau khi khóa trả mã 403, thông báo Tài khoản của bạn đã bị khóa. (UC23 ngoại lệ 3a) | I20: Security | J20: Cao | K20: Tự động | L20: Trước khi khóa mã 200; sau khi khóa mã 403 với đúng thông báo. Kịch bản AUTH-019b xác nhận thêm tài khoản customer.locked bị chặn ngay ở bước đăng nhập (mã 403, không cấp token, ngoại lệ 5c) | M20: Pass | N20: Jest + Supertest | O20: 25/09/2026
A21: AUTH-020 | B21: Xác thực và phân quyền | C21: UC03 | D21: Gọi API được bảo vệ khi không gửi token | E21: Máy chủ đang chạy | F21: Yêu cầu GET /api/users/me không có header Authorization | G21: 1. Gửi yêu cầu | H21: Mã 401, thông báo Token không tồn tại | I21: Security | J21: Cao | K21: Tự động | L21: Mã 401, Token không tồn tại | M21: Pass | N21: Jest + Supertest | O21: 25/09/2026
A22: AUTH-021 | B22: Xác thực và phân quyền | C22: UC03 | D22: Gọi API với token sai định dạng hoặc đã hết hạn | E22: Máy chủ đang chạy | F22: Bearer abc.def.ghi; token hợp lệ về chữ ký nhưng hết hạn từ 1 giờ trước | G22: 1. Gửi yêu cầu kèm token sai định dạng 2. Gửi yêu cầu kèm token hết hạn | H22: Cả hai trường hợp trả mã 401, thông báo Token không hợp lệ (ngoại lệ 1a) | I22: Security | J22: Cao | K22: Tự động | L22: Cả hai trả mã 401, Token không hợp lệ (trường hợp hết hạn chạy ở kịch bản AUTH-021b) | M22: Pass | N22: Jest + Supertest | O22: 25/09/2026
A23: AUTH-022 | B23: Xác thực và phân quyền | C23: UC03 | D23: Đăng xuất và xác nhận phiên đã kết thúc | E23: Đang đăng nhập trên trình duyệt | F23: Không | G23: 1. Nhấn Đăng xuất 2. Kiểm tra localStorage 3. Truy cập lại trang cần đăng nhập | H23: Dữ liệu xác thực trong localStorage bị xóa, trình duyệt chuyển về /login và không vào lại được trang bảo vệ (hậu điều kiện UC03) | I23: Positive | J23: Cao | K23: Tự động | L23: Chưa có kết quả; UC03 không có điểm cuối API, toàn bộ xử lý nằm ở giao diện | M23: Chưa thực hiện | P23: Lý do: chức năng nằm hoàn toàn ở giao diện, thuộc giai đoạn 6 chưa triển khai (Bảng 3.38, dòng 1)
A24: AUTH-023 | B24: Xác thực và phân quyền | C24: UC04 | D24: Xem và cập nhật hồ sơ cá nhân | E24: customer1 đã đăng nhập | F24: name = Khach hang mot da doi ten; phone = 0987654321 | G24: 1. Gửi GET /api/users/me 2. Gửi PUT /api/users/me 3. Truy vấn bảng users | H24: Mã 200 ở cả hai yêu cầu; họ tên và số điện thoại mới được lưu (bước 5) | I24: Positive | J24: Cao | K24: Tự động | L24: Cả hai yêu cầu trả mã 200; cột name và phone mang đúng giá trị mới. Phần hiển thị sau khi tải lại trang chưa kiểm chứng | M24: Pass | N24: Jest + Supertest | O24: 25/09/2026 | P24: Mức kiểm chứng hạn chế: phần giao diện hoặc thời gian thực chưa kiểm chứng (Bảng 3.37, dòng 4)
A25: AUTH-024 | B25: Xác thực và phân quyền | C25: UC04 | D25: Đổi mật khẩu với mật khẩu hiện tại không đúng | E25: customer2 đã đăng nhập | F25: currentPassword = SaiMatKhauCu; newPassword = MatKhauMoi@123 | G25: 1. Gửi PUT /api/users/me/change-password 2. So sánh cột password trước và sau | H25: Mã 401, thông báo Mật khẩu hiện tại không đúng; cột password không thay đổi (ngoại lệ 3a) | I25: Security | J25: Cao | K25: Tự động | L25: Yêu cầu bị từ chối (kịch bản kiểm tra mã từ 400 trở lên); cột password giữ nguyên. Kịch bản AUTH-024b xác nhận mật khẩu mới dưới 6 ký tự bị từ chối với mã 400 | M25: Pass | N25: Jest + Supertest | O25: 25/09/2026 | P25: Mức kiểm chứng hạn chế: chỉ kiểm tra mã trạng thái (Bảng 3.37, dòng 1)
A26: AUTH-025 | B26: Xác thực và phân quyền | C26: UC04 | D26: Cập nhật ảnh đại diện | E26: Người dùng đã đăng nhập | F26: avatar.png dung lượng 500 KB | G26: 1. Mở trang Hồ sơ 2. Chọn ảnh mới 3. Nhấn Tải lên | H26: Ảnh được lưu vào thư mục uploads, cột avatar được cập nhật, ảnh mới hiển thị trên thanh điều hướng | I26: Positive | J26: Trung bình | K26: Tự động | L26: Chưa có kết quả đủ tin cậy; kịch bản USR-007 có gọi POST /api/users/me/avatar nhưng tự bỏ qua bước kiểm tra khi máy chủ trả lỗi | M26: Chưa thực hiện | P26: Lý do: kịch bản hiện có chưa đủ tin cậy làm bằng chứng (Bảng 3.38, dòng 2)

Sheet PROD
A1: Mã TC | B1: Nhóm chức năng | C1: UC liên quan | D1: Tiêu đề kiểm thử | E1: Điều kiện tiên quyết | F1: Dữ liệu đầu vào | G1: Các bước thực hiện | H1: Kết quả mong đợi | I1: Loại KT | J1: Mức ưu tiên | K1: Phương pháp | L1: Kết quả thực tế | M1: Trạng thái | N1: Người thực hiện | O1: Ngày thực hiện | P1: Ghi chú
A2: PROD-001 | B2: Quản lý sản phẩm và tồn kho | C2: UC05 | D2: Xem danh sách sản phẩm khi chưa đăng nhập | E2: Dữ liệu mẫu có 18 sản phẩm active và 3 sản phẩm pending | F2: Không gửi token | G2: 1. Gửi GET /api/products 2. Đối chiếu với các sản phẩm có status khác active hoặc đã xóa mềm | H2: Mã 200; chỉ có sản phẩm status = active và chưa bị xóa mềm (bước 2) | I2: Positive | J2: Cao | K2: Tự động | L2: Mã 200; không mã sản phẩm pending hay đã xóa mềm nào xuất hiện trong danh sách | M2: Pass | N2: Jest + Supertest | O2: 25/09/2026
A3: PROD-002 | B3: Quản lý sản phẩm và tồn kho | C3: UC05 | D3: Lọc sản phẩm theo danh mục | E3: 4 danh mục đều có sản phẩm | F3: Danh mục đầu tiên có product_count lớn hơn 0 | G3: 1. Gửi GET /api/categories 2. Gửi GET /api/products và lọc theo tên danh mục 3. Đếm trực tiếp trong cơ sở dữ liệu | H3: Chỉ còn sản phẩm thuộc danh mục đã chọn; số lượng khớp số sản phẩm của danh mục (bước 3) | I3: Positive | J3: Cao | K3: Tự động | L3: Số sản phẩm sau khi lọc bằng số đếm trong cơ sở dữ liệu. Thao tác lọc do Shop.js thực hiện trên trình duyệt nên phần hiển thị chưa kiểm chứng | M3: Pass | N3: Jest + Supertest | O3: 25/09/2026 | P3: Mức kiểm chứng hạn chế: phần giao diện hoặc thời gian thực chưa kiểm chứng (Bảng 3.37, dòng 4)
A4: PROD-003 | B4: Quản lý sản phẩm và tồn kho | C4: UC05 | D4: Tìm kiếm theo từ khóa có kết quả | E4: Có sản phẩm tên chứa từ khóa | F4: keyword = Kiem Thu | G4: 1. Nhập từ khóa vào ô tìm kiếm 2. Nhấn tìm kiếm | H4: Hiển thị đúng các sản phẩm có tên chứa từ khóa, không phân biệt chữ hoa và chữ thường (bước 3) | I4: Positive | J4: Trung bình | K4: Tự động | L4: Chưa có kết quả; tìm kiếm là bộ lọc trên trình duyệt trong Shop.js, máy chủ không nhận tham số tìm kiếm | M4: Chưa thực hiện | P4: Lý do: chức năng nằm hoàn toàn ở giao diện, thuộc giai đoạn 6 chưa triển khai (Bảng 3.38, dòng 1)
A5: PROD-004 | B5: Quản lý sản phẩm và tồn kho | C5: UC05 | D5: Tìm kiếm với từ khóa không khớp sản phẩm nào | E5: Đang ở trang danh sách sản phẩm | F5: keyword = zzzzzzzz | G5: 1. Nhập từ khóa 2. Nhấn tìm kiếm | H5: Hiển thị thông báo không tìm thấy, không báo lỗi hệ thống (ngoại lệ 3a) | I5: Negative | J5: Trung bình | K5: Tự động | L5: Chưa có kết quả; cùng lý do với PROD-003 | M5: Chưa thực hiện | P5: Lý do: chức năng nằm hoàn toàn ở giao diện, thuộc giai đoạn 6 chưa triển khai (Bảng 3.38, dòng 1)
A6: PROD-005 | B6: Quản lý sản phẩm và tồn kho | C6: UC05 | D6: Xem chi tiết sản phẩm hợp lệ | E6: Tồn tại sản phẩm có id xác định | F6: Mã của sản phẩm đầu tiên trong danh sách công khai | G6: 1. Gửi GET /api/products/:id | H6: Mã 200; đủ tên, giá, giá gốc, mô tả, ảnh, tồn kho, danh sách biến thể và đánh giá (bước 5) | I6: Positive | J6: Cao | K6: Tự động | L6: Mã 200; có các trường id, name, price, stock. Các trường còn lại chưa được kịch bản kiểm tra | M6: Pass | N6: Jest + Supertest | O6: 25/09/2026 | P6: Mức kiểm chứng hạn chế: chỉ kiểm tra một phần kết quả mong đợi (Bảng 3.37, dòng 2)
A7: PROD-006 | B7: Quản lý sản phẩm và tồn kho | C7: UC05 | D7: Xem chi tiết sản phẩm với mã không tồn tại | E7: Máy chủ đang chạy | F7: productId = 999999 | G7: 1. Gửi GET /api/products/999999 | H7: Mã 404, không trả lỗi 500 (ngoại lệ 4a) | I7: Negative | J7: Trung bình | K7: Tự động | L7: Mã 404 | M7: Pass | N7: Jest + Supertest | O7: 25/09/2026
A8: PROD-007 | B8: Quản lý sản phẩm và tồn kho | C8: UC05 | D8: Xem danh sách biến thể | E8: 3 sản phẩm đầu có biến thể Size S, M, L | F8: Mã của một sản phẩm có biến thể | G8: 1. Gửi GET /api/variants/product/:id | H8: Mã 200; mỗi biến thể có tên, giá và tồn kho riêng | I8: Positive | J8: Cao | K8: Tự động | L8: Mã 200; danh sách có biến thể, bản ghi đầu có đủ variant_name, price, stock | M8: Pass | N8: Jest + Supertest | O8: 25/09/2026
A9: PROD-008 | B9: Quản lý sản phẩm và tồn kho | C9: UC12 | D9: Quản lý thêm sản phẩm mới hợp lệ | E9: Đăng nhập manager@tigershop.test | F9: name = SP cua Manager [thời điểm]; price = 250000; stock = 50; ảnh PNG hợp lệ | G9: 1. Gửi POST /api/products dạng multipart 2. Truy vấn status và manager_id của sản phẩm mới | H9: Mã 200; sản phẩm có status = pending và manager_id là người tạo; chưa hiển thị trên gian hàng cho tới khi được duyệt (bước 5, hậu điều kiện UC12) | I9: Positive | J9: Cao | K9: Tự động | L9: Mã 200; sản phẩm có status = active ngay khi tạo, tức là lên gian hàng mà không qua bước duyệt | M9: Fail | N9: Jest + Supertest | O9: 25/09/2026 | P9: Khiếm khuyết DEF-02, mức Cao (Bảng 3.36); kịch bản PROD-008b ghi nhận thêm DEF-03
A10: PROD-009 | B10: Quản lý sản phẩm và tồn kho | C10: UC12 | D10: Thêm sản phẩm khi bỏ trống tên và giá | E10: Đăng nhập Quản lý | F10: name rỗng; price rỗng | G10: 1. Gửi POST /api/products | H10: Mã 400, thông báo Thiếu thông tin sản phẩm (ngoại lệ 2a) | I10: Negative | J10: Cao | K10: Tự động | L10: Mã 400, Thiếu thông tin sản phẩm | M10: Pass | N10: Jest + Supertest | O10: 25/09/2026
A11: PROD-010 | B11: Quản lý sản phẩm và tồn kho | C11: UC12 | D11: Tải lên tệp sai định dạng | E11: Đăng nhập Quản lý | F11: tailieu.pdf | G11: 1. Gửi POST /api/products kèm tệp pdf ở trường image | H11: Từ chối tải lên, chỉ chấp nhận jpg, jpeg, png, webp (ngoại lệ 3a) | I11: Security | J11: Cao | K11: Tự động | L11: Yêu cầu bị từ chối (kịch bản chỉ kiểm tra mã từ 400 trở lên); bộ lọc fileFilter trong productRoutes.js chặn tệp trước khi ghi đĩa | M11: Pass | N11: Jest + Supertest | O11: 25/09/2026 | P11: Mức kiểm chứng hạn chế: chỉ kiểm tra mã trạng thái (Bảng 3.37, dòng 1)
A12: PROD-011 | B12: Quản lý sản phẩm và tồn kho | C12: UC12 | D12: Tải lên ảnh vượt giới hạn dung lượng | E12: Đăng nhập Quản lý | F12: anh_lon.jpg dung lượng 6 MB | G12: 1. Gửi POST /api/products kèm tệp | H12: Từ chối tải lên vì vượt giới hạn 5 MB (ngoại lệ 3a) | I12: Boundary | J12: Cao | K12: Tự động | L12: Yêu cầu bị từ chối (kịch bản chỉ kiểm tra mã từ 400 trở lên) | M12: Pass | N12: Jest + Supertest | O12: 25/09/2026 | P12: Mức kiểm chứng hạn chế: chỉ kiểm tra mã trạng thái (Bảng 3.37, dòng 1)
A13: PROD-012 | B13: Quản lý sản phẩm và tồn kho | C13: UC12 | D13: Cập nhật thông tin sản phẩm | E13: Đăng nhập Quản lý | F13: price = 299000; stock = 80 | G13: 1. Gửi PUT /api/products/:id 2. Truy vấn price và stock | H13: Mã 200; giá và tồn kho được cập nhật đúng (bước 7) | I13: Positive | J13: Cao | K13: Tự động | L13: Mã 200; price = 299000, stock = 80 | M13: Pass | N13: Jest + Supertest | O13: 25/09/2026
A14: PROD-013 | B14: Quản lý sản phẩm và tồn kho | C14: UC12 | D14: Xóa mềm và khôi phục sản phẩm | E14: Sản phẩm đang active | F14: Mã của một sản phẩm active | G14: 1. Gửi DELETE /api/products/:id 2. Gửi GET /api/products 3. Gửi PATCH /api/products/:id/restore | H14: Sau khi xóa: deleted_at có giá trị, sản phẩm biến mất khỏi gian hàng. Sau khi khôi phục: deleted_at trở về NULL (ngoại lệ 7b) | I14: Positive | J14: Cao | K14: Tự động | L14: Cả hai thao tác trả mã 200; deleted_at có giá trị rồi trở về NULL; trong khoảng giữa, sản phẩm không có trong danh sách công khai | M14: Pass | N14: Jest + Supertest | O14: 25/09/2026
A15: PROD-014 | B15: Quản lý sản phẩm và tồn kho | C15: UC12 | D15: Thêm biến thể cho sản phẩm | E15: Đăng nhập Quản lý | F15: variant_name = Size XL mau do; price = 270000; stock = 20 | G15: 1. Gửi POST /api/variants 2. Truy vấn product_variants | H15: Mã 200, thông báo Thêm variant thành công; bản ghi biến thể được tạo (bước 6) | I15: Positive | J15: Cao | K15: Tự động | L15: Mã 200, Thêm variant thành công; bản ghi có stock = 20 | M15: Pass | N15: Jest + Supertest | O15: 25/09/2026
A16: PROD-015 | B16: Quản lý sản phẩm và tồn kho | C16: UC12 | D16: Thêm biến thể khi thiếu dữ liệu bắt buộc | E16: Đăng nhập bằng tài khoản MANAGER | F16: variant_name rỗng; price rỗng | G16: 1. Gửi POST /api/variants | H16: Mã 400, thông báo Thiếu dữ liệu variant (ngoại lệ 6a) | I16: Negative | J16: Trung bình | K16: Tự động | L16: Mã 400, Thiếu dữ liệu variant | M16: Pass | N16: Jest + Supertest | O16: 25/09/2026
A17: PROD-016 | B17: Quản lý sản phẩm và tồn kho | C17: UC12 | D17: Cập nhật tồn kho hàng loạt | E17: Sản phẩm có 3 biến thể | F17: Mảng updates gồm 3 cặp mã biến thể và tồn kho mới 5, 10, 15 | G17: 1. Gửi PUT /api/variants/bulk-stock 2. Truy vấn tồn kho các biến thể | H17: Cả 3 biến thể được cập nhật đúng; tổng tồn kho của sản phẩm cha được tính lại chính xác (ngoại lệ 7c) | I17: Positive | J17: Trung bình | K17: Tự động | L17: Mã 200; tồn kho 3 biến thể lần lượt đúng 5, 10, 15. Tổng tồn kho của sản phẩm cha chưa được kịch bản đối chiếu | M17: Pass | N17: Jest + Supertest | O17: 25/09/2026 | P17: Mức kiểm chứng hạn chế: chỉ kiểm tra một phần kết quả mong đợi (Bảng 3.37, dòng 2)
A18: PROD-017 | B18: Quản lý sản phẩm và tồn kho | C18: UC13 | D18: Quản trị viên duyệt sản phẩm chờ | E18: Có sản phẩm pending; đăng nhập admin@tigershop.test | F18: status = active | G18: 1. Gửi PATCH /api/products/:id/decision 2. Truy vấn products và user_activity_logs | H18: status chuyển thành active; sản phẩm xuất hiện trên gian hàng; nhật ký ghi lại quyết định (bước 4, 5) | I18: Positive | J18: Cao | K18: Tự động | L18: Mã 200; status = active; user_activity_logs có bản ghi mới chứa nội dung Duyệt sản phẩm | M18: Pass | N18: Jest + Supertest | O18: 25/09/2026
A19: PROD-018 | B19: Quản lý sản phẩm và tồn kho | C19: UC13 | D19: Quản trị viên từ chối sản phẩm kèm lý do | E19: Có sản phẩm pending | F19: status = hidden; reason = Anh san pham khong dat chuan | G19: 1. Gửi PATCH /api/products/:id/decision 2. Truy vấn status và rejection_reason | H19: status chuyển thành hidden và rejection_reason lưu đúng lý do (ngoại lệ 3a) | I19: Positive | J19: Cao | K19: Tự động | L19: Mã 200; status = hidden; rejection_reason đúng nội dung. Kịch bản PROD-018b xác nhận giá trị nằm ngoài active và hidden bị từ chối với mã 400, Trạng thái không hợp lệ (ngoại lệ 3b) | M19: Pass | N19: Jest + Supertest | O19: 25/09/2026
A20: PROD-019 | B20: Quản lý sản phẩm và tồn kho | C20: UC13 | D20: Nhân viên cố gọi điểm cuối duyệt sản phẩm | E20: Đăng nhập bằng tài khoản STAFF | F20: token của staff@tigershop.test | G20: 1. Gửi PATCH /api/products/:id/decision | H20: Mã 403 (ngoại lệ 1a) | I20: Security | J20: Cao | K20: Tự động | L20: Mã 403 | M20: Pass | N20: Jest + Supertest | O20: 25/09/2026
A21: PROD-020 | B21: Quản lý sản phẩm và tồn kho | C21: UC13 | D21: Đưa sản phẩm đã bị từ chối trở lại hàng đợi duyệt | E21: Có sản phẩm status = hidden | F21: Mã của sản phẩm bị từ chối | G21: 1. Mở danh sách sản phẩm đã quyết định 2. Chọn sản phẩm 3. Nhấn Gửi duyệt lại | H21: status trở về pending, rejection_reason bị xóa, sản phẩm xuất hiện lại trong danh sách chờ (ngoại lệ 6a) | I21: Positive | J21: Trung bình | K21: Tự động | L21: Chưa có kết quả; điểm cuối PATCH /api/products/:id/restore-pending thuộc 14 điểm cuối chưa được bộ kiểm thử gọi tới (Bảng 2.13) | M21: Chưa thực hiện | P21: Lý do: có thể kiểm thử ở mức API nhưng chưa có kịch bản (Bảng 3.38, dòng 5)
A22: PROD-021 | B22: Quản lý sản phẩm và tồn kho | C22: UC14 | D22: Xem cảnh báo tồn kho thấp | E22: Dữ liệu mẫu có 3 sản phẩm tồn kho 3, 2 và 1 | F22: token của manager@tigershop.test | G22: 1. Gửi GET /api/products/inventory-alert | H22: Danh sách sản phẩm chưa bị xóa có tồn kho dưới 5, sắp xếp tăng dần (bước 2), kèm số sản phẩm trong thùng rác | I22: Positive | J22: Cao | K22: Tự động | L22: Mã 200; mọi mục đều có stock dưới 5 và theo thứ tự tăng dần. Số sản phẩm trong thùng rác chưa được kiểm tra | M22: Pass | N22: Jest + Supertest | O22: 25/09/2026 | P22: Mức kiểm chứng hạn chế: chỉ kiểm tra một phần kết quả mong đợi (Bảng 3.37, dòng 2)
A23: PROD-022 | B23: Quản lý sản phẩm và tồn kho | C23: UC14 | D23: Nhập thêm hàng và kiểm tra nhật ký kho | E23: Đăng nhập Quản lý | F23: quantity = 50; note = Nhap bo sung | G23: 1. Gửi POST /api/users/inventory/restock 2. Truy vấn stock 3. Truy vấn inventory_logs | H23: Tồn kho tăng đúng 50; inventory_logs ghi old_stock, new_stock, quantity_added và manager_id (hậu điều kiện UC14) | I23: Positive | J23: Cao | K23: Tự động | L23: Tồn kho tăng đúng 50 so với giá trị ban đầu; bản ghi inventory_logs có old_stock, new_stock và quantity_added = 50 đúng. Cột manager_id chưa được kiểm tra | M23: Pass | N23: Jest + Supertest | O23: 25/09/2026 | P23: Mức kiểm chứng hạn chế: chỉ kiểm tra một phần kết quả mong đợi (Bảng 3.37, dòng 2)

Sheet ORD
A1: Mã TC | B1: Nhóm chức năng | C1: UC liên quan | D1: Tiêu đề kiểm thử | E1: Điều kiện tiên quyết | F1: Dữ liệu đầu vào | G1: Các bước thực hiện | H1: Kết quả mong đợi | I1: Loại KT | J1: Mức ưu tiên | K1: Phương pháp | L1: Kết quả thực tế | M1: Trạng thái | N1: Người thực hiện | O1: Ngày thực hiện | P1: Ghi chú
A2: ORD-001 | B2: Giỏ hàng và đơn hàng | C2: UC06 | D2: Thêm sản phẩm không có biến thể vào giỏ | E2: customer1 đã đăng nhập, sản phẩm còn hàng | F2: quantity = 2 | G2: 1. Mở trang chi tiết sản phẩm 2. Nhập số lượng 2 3. Nhấn Thêm vào giỏ | H2: Sản phẩm có trong giỏ với đúng số lượng; biểu tượng giỏ hàng cập nhật (bước 3) | I2: Positive | J2: Cao | K2: Tự động | L2: Chưa có kết quả | M2: Chưa thực hiện | P2: Lý do: chức năng nằm hoàn toàn ở giao diện, thuộc giai đoạn 6 chưa triển khai (Bảng 3.38, dòng 1)
A3: ORD-002 | B3: Giỏ hàng và đơn hàng | C3: UC06 | D3: Thêm sản phẩm có biến thể nhưng chưa chọn biến thể | E3: Sản phẩm có Size S, M, L | F3: Không chọn biến thể | G3: 1. Mở trang chi tiết 2. Nhấn Thêm vào giỏ | H3: Hiển thị cảnh báo; không thêm vào giỏ (ngoại lệ 1a) | I3: Negative | J3: Cao | K3: Tự động | L3: Chưa có kết quả | M3: Chưa thực hiện | P3: Lý do: chức năng nằm hoàn toàn ở giao diện, thuộc giai đoạn 6 chưa triển khai (Bảng 3.38, dòng 1)
A4: ORD-003 | B4: Giỏ hàng và đơn hàng | C4: UC06 | D4: Thêm số lượng vượt tồn kho | E4: San pham ton kho thap A còn 3 | F4: quantity = 10 | G4: 1. Nhập số lượng 10 2. Nhấn Thêm vào giỏ | H4: Cảnh báo và giới hạn số lượng theo tồn kho là 3 (ngoại lệ 2a) | I4: Boundary | J4: Cao | K4: Tự động | L4: Chưa có kết quả | M4: Chưa thực hiện | P4: Lý do: chức năng nằm hoàn toàn ở giao diện, thuộc giai đoạn 6 chưa triển khai (Bảng 3.38, dòng 1)
